Workbook

Sheet 2.7 exo moco optimization
A1: 2.7 m/s simulations | F1: Natural comparison
A2: duration (sec) | B2: Avg. Metabolic rate [W/kg] | C2: exo stiffness [N/m] | D2: exo rest length [m] | F2: duration (sec) | G2: Avg. Metabolic rate [W/kg] | H2: exo stiffness [N/m] | I2: exo rest length [m]
A3: 0.7235 | B3: 9.87752 | C3: 354.19836 | D3: 0.45984949 | F3: 0.7235
A4: 0.7235 | B4: 9.852252 | C4: 341.72659 | D4: 0.4596629 | F4: 0.7235
A5: 0.6835 | B5: 9.308189 | C5: 409.90579 | D5: 0.43152207 | F5: 0.6835 | G5: 9.312821 | H5: 120 | I5: 0.2869
A6: 0.648 | B6: 9.120665 | C6: 504.73035 | D6: 0.42428103 | F6: 0.648 | G6: 9.071919 | H6: 120 | I6: 0.2869
A7: 0.608 | B7: 9.286039 | C7: 494.475 | D7: 0.37576899 | F7: 0.608
A8: 0.568 | B8: 10.000717 | C8: 444.26892 | D8: 0.33724368 | F8: 0.568
A11: diff weights | F11: diff weights
A12: 0.6835 | B12: 8.960073 | C12: 396.79178 | D12: 0.4340601 | F12: 0.6835 | G12: 8.917185 | H12: 120 | I12: 0.2869
A13: 0.648 | B13: 8.776368 | C13: 478.2245 | D13: 0.42627332 | F13: 0.648 | G13: 8.730262 | H13: 120 | I13: 0.2869
F16: 0.6835 | G16: 8.918058 | H16: 120 | I16: 0.2869
A17: 0.648 | B17: 8.777274 | C17: 482.83658 | D17: 0.42774646 | F17: 0.648 | G17: 8.727464 | H17: 120 | I17: 0.2869

Sheet 2.7 exo sweep
B7: metabolic values | I7: percent savings | Q7: Bottom of the bowl savings. | U7: Table
B8: time | D8: 0.608 | E8: 0.648 | F8: 0.6835 | G8: 0.7235 | I8: time | L8: 0.608 | M8: 0.648 | N8: 0.6835 | O8: 0.7235
X9: exotendon length (m)
H10: minimums | X10: l=0.1435 | Y10: l=0.2869 | Z10: l=0.4305
B11: natural | D11: 11.35727 | E11: 10.63512 | F11: 10.62359 | G11: 11.35107 | H11: =MIN(D11:G11) -> 10.62359 | J11: natural | R11: natural | V11: exotendon stiffness (N/m) | W11: 60 | X11: -0.69129174 | Y11: 0.99081384 | Z11: 2.0490249
W12: 120 | X12: -2.6598353 | Y12: -3.6208099 | Z12: 0.97274085
A13: length | B13: stiff | I13: length | J13: stiff | Q13: length | R13: stiff | W13: 180 | X13: -2.0255865 | Y13: -3.5391991 | Z13: -0.24850357
A14: nom | B14: compliant | D14: 12.02204 | E14: 11.05707 | F14: 10.74434 | G14: 10.72885 | H14: =MIN(D14:G14) -> 10.72885 | I14: nom | J14: compliant | L14: =(D14-D$11)/D$11*100 -> 5.8532552 | M14: =(E14-E$11)/E$11*100 -> 3.9675152 | N14: =(F14-F$11)/F$11*100 -> 1.1366214 | O14: =(G14-G$11)/G$11*100 -> -5.4815978 | Q14: nom | R14: compliant | S14: =(H14-H$11)/H$11*100 -> 0.99081384
A15: nom | B15: nom | D15: 11.01363 | E15: 10.24297 | F15: 10.23893 | G15: 10.81166 | H15: =MIN(D15:G15) -> 10.23893 | I15: nom | J15: nom | L15: =(D15-D$11)/D$11*100 -> -3.0257271 | M15: =(E15-E$11)/E$11*100 -> -3.6873115 | N15: =(F15-F$11)/F$11*100 -> -3.6208099 | O15: =(G15-G$11)/G$11*100 -> -4.752063 | Q15: nom | R15: nom | S15: =(H15-H$11)/H$11*100 -> -3.6208099
A16: nom | B16: stiff | D16: 11.46436 | E16: 10.72302 | F16: 10.2476 | G16: 10.40551 | H16: =MIN(D16:G16) -> 10.2476 | I16: nom | J16: stiff | L16: =(D16-D$11)/D$11*100 -> 0.94292026 | M16: =(E16-E$11)/E$11*100 -> 0.82650689 | N16: =(F16-F$11)/F$11*100 -> -3.5391991 | O16: =(G16-G$11)/G$11*100 -> -8.3301398 | Q16: nom | R16: stiff | S16: =(H16-H$11)/H$11*100 -> -3.5391991
A18: short | B18: compliant | D18: 11.7456 | E18: 11.02282 | F18: 10.70454 | G18: 10.55015 | H18: =MIN(D18:G18) -> 10.55015 | I18: short | J18: compliant | L18: =(D18-D$11)/D$11*100 -> 3.4192196 | M18: =(E18-E$11)/E$11*100 -> 3.645469 | N18: =(F18-F$11)/F$11*100 -> 0.76198347 | O18: =(G18-G$11)/G$11*100 -> -7.0558987 | Q18: short | R18: compliant | S18: =(H18-H$11)/H$11*100 -> -0.69129174
A19: short | B19: nom | D19: 11.50045 | E19: 10.82032 | F19: 10.34102 | G19: 10.37026 | H19: =MIN(D19:G19) -> 10.34102 | I19: short | J19: nom | L19: =(D19-D$11)/D$11*100 -> 1.2606903 | M19: =(E19-E$11)/E$11*100 -> 1.7414002 | N19: =(F19-F$11)/F$11*100 -> -2.6598353 | O19: =(G19-G$11)/G$11*100 -> -8.6406832 | Q19: short | R19: nom | S19: =(H19-H$11)/H$11*100 -> -2.6598353
A20: short | B20: stiff | D20: 11.50211 | E20: 10.67199 | F20: 10.4084 | G20: 10.70873 | H20: =MIN(D20:G20) -> 10.4084 | I20: short | J20: stiff | L20: =(D20-D$11)/D$11*100 -> 1.2753065 | M20: =(E20-E$11)/E$11*100 -> 0.34668156 | N20: =(F20-F$11)/F$11*100 -> -2.0255865 | O20: =(G20-G$11)/G$11*100 -> -5.6588498 | Q20: short | R20: stiff | S20: =(H20-H$11)/H$11*100 -> -2.0255865
A22: long | B22: compliant | D22: 11.90847 | E22: 11.31396 | F22: 10.84127 | G22: 10.91077 | H22: =MIN(D22:G22) -> 10.84127 | I22: long | J22: compliant | L22: =(D22-D$11)/D$11*100 -> 4.853279 | M22: =(E22-E$11)/E$11*100 -> 6.3830027 | N22: =(F22-F$11)/F$11*100 -> 2.0490249 | O22: =(G22-G$11)/G$11*100 -> -3.8789295 | Q22: long | R22: compliant | S22: =(H22-H$11)/H$11*100 -> 2.0490249
A23: long | B23: nom | D23: 12.02442 | E23: 11.12339 | F23: 10.72693 | G23: 10.75698 | H23: =MIN(D23:G23) -> 10.72693 | I23: long | J23: nom | L23: =(D23-D$11)/D$11*100 -> 5.874211 | M23: =(E23-E$11)/E$11*100 -> 4.5911095 | N23: =(F23-F$11)/F$11*100 -> 0.97274085 | O23: =(G23-G$11)/G$11*100 -> -5.2337797 | Q23: long | R23: nom | S23: =(H23-H$11)/H$11*100 -> 0.97274085
A24: long | B24: stiff | D24: 11.78364 | E24: 10.95742 | F24: 10.62823 | G24: 10.59719 | H24: =MIN(D24:G24) -> 10.59719 | I24: long | J24: stiff | L24: =(D24-D$11)/D$11*100 -> 3.7541592 | M24: =(E24-E$11)/E$11*100 -> 3.0305253 | N24: =(F24-F$11)/F$11*100 -> 0.043676384 | O24: =(G24-G$11)/G$11*100 -> -6.6414884 | Q24: long | R24: stiff | S24: =(H24-H$11)/H$11*100 -> -0.24850357

Sheet 4 exo sweep
B7: metabolic values | I7: percent savings | Q7: Bottom of the bowl savings. | U7: Table
B8: time | D8: 0.604 | E8: 0.644 | F8: 0.684 | G8: 0.724 | I8: time | L8: 0.608 | M8: 0.648 | N8: 0.6835 | O8: 0.7235
X9: exotendon length (m)
H10: minimums | X10: l=0.1435 | Y10: l=0.2869 | Z10: l=0.4305
B11: natural | D11: 15.18577 | E11: 15.18749 | F11: 15.21813 | G11: 15.38369 | H11: =MIN(D11:G11) -> 15.18577 | J11: natural | R11: natural | V11: exotendon stiffness (N/m) | W11: 60 | X11: 20.328031 | Y11: 7.2871511 | Z11: 9.1468065
W12: 120 | X12: 7.5591162 | Y12: -12.934675 | Z12: 6.4639462
A13: length | B13: stiff | I13: length | J13: stiff | Q13: length | R13: stiff | W13: 180 | X13: 7.7052069 | Y13: 2.971927 | Z13: 14.357342
A14: nom | B14: compliant | E14: 18.29168 | F14: 16.70396 | G14: 16.29238 | H14: =MIN(D14:G14) -> 16.29238 | I14: nom | J14: compliant | L14: =(D14-D$11)/D$11*100 -> -100 | M14: =(E14-E$11)/E$11*100 -> 20.439125 | N14: =(F14-F$11)/F$11*100 -> 9.7635518 | O14: =(G14-G$11)/G$11*100 -> 5.9068403 | Q14: nom | R14: compliant | S14: =(H14-H$11)/H$11*100 -> 7.2871511
A15: nom | B15: nom | D15: 13.22154 | E15: 13.25094 | F15: 13.97647 | G15: 14.99654 | H15: =MIN(D15:G15) -> 13.22154 | I15: nom | J15: nom | L15: =(D15-D$11)/D$11*100 -> -12.934675 | M15: =(E15-E$11)/E$11*100 -> -12.750955 | N15: =(F15-F$11)/F$11*100 -> -8.1590839 | O15: =(G15-G$11)/G$11*100 -> -2.5166264 | Q15: nom | R15: nom | S15: =(H15-H$11)/H$11*100 -> -12.934675
A16: nom | B16: stiff | E16: 17.02516 | F16: 15.63708 | H16: =MIN(D16:G16) -> 15.63708 | I16: nom | J16: stiff | L16: =(D16-D$11)/D$11*100 -> -100 | M16: =(E16-E$11)/E$11*100 -> 12.099893 | N16: =(F16-F$11)/F$11*100 -> 2.7529664 | O16: =(G16-G$11)/G$11*100 -> -100 | Q16: nom | R16: stiff | S16: =(H16-H$11)/H$11*100 -> 2.971927
A18: short | B18: compliant | D18: 18.272738 | H18: =MIN(D18:G18) -> 18.272738 | I18: short | J18: compliant | L18: =(D18-D$11)/D$11*100 -> 20.328031 | M18: =(E18-E$11)/E$11*100 -> -100 | N18: =(F18-F$11)/F$11*100 -> -100 | O18: =(G18-G$11)/G$11*100 -> -100 | Q18: short | R18: compliant | S18: =(H18-H$11)/H$11*100 -> 20.328031
A19: short | B19: nom | F19: 16.33368 | G19: 17.91933 | H19: =MIN(D19:G19) -> 16.33368 | I19: short | J19: nom | L19: =(D19-D$11)/D$11*100 -> -100 | M19: =(E19-E$11)/E$11*100 -> -100 | N19: =(F19-F$11)/F$11*100 -> 7.3304013 | O19: =(G19-G$11)/G$11*100 -> 16.482651 | Q19: short | R19: nom | S19: =(H19-H$11)/H$11*100 -> 7.5591162
A20: short | B20: stiff | E20: 16.355865 | G20: 19.728766 | H20: =MIN(D20:G20) -> 16.355865 | I20: short | J20: stiff | L20: =(D20-D$11)/D$11*100 -> -100 | M20: =(E20-E$11)/E$11*100 -> 7.6930092 | N20: =(F20-F$11)/F$11*100 -> -100 | O20: =(G20-G$11)/G$11*100 -> 28.244693 | Q20: short | R20: stiff | S20: =(H20-H$11)/H$11*100 -> 7.7052069
A22: long | B22: compliant | E22: 17.073769 | F22: 16.574783 | G22: 16.797293 | H22: =MIN(D22:G22) -> 16.574783 | I22: long | J22: compliant | L22: =(D22-D$11)/D$11*100 -> -100 | M22: =(E22-E$11)/E$11*100 -> 12.419952 | N22: =(F22-F$11)/F$11*100 -> 8.9147155 | O22: =(G22-G$11)/G$11*100 -> 9.1889722 | Q22: long | R22: compliant | S22: =(H22-H$11)/H$11*100 -> 9.1468065
A23: long | B23: nom | E23: 17.45434 | F23: 16.16737 | H23: =MIN(D23:G23) -> 16.16737 | I23: long | J23: nom | L23: =(D23-D$11)/D$11*100 -> -100 | M23: =(E23-E$11)/E$11*100 -> 14.925771 | N23: =(F23-F$11)/F$11*100 -> 6.2375601 | O23: =(G23-G$11)/G$11*100 -> -100 | Q23: long | R23: nom | S23: =(H23-H$11)/H$11*100 -> 6.4639462
A24: long | B24: stiff | D24: 17.366043 | H24: =MIN(D24:G24) -> 17.366043 | I24: long | J24: stiff | L24: =(D24-D$11)/D$11*100 -> 14.357342 | M24: =(E24-E$11)/E$11*100 -> -100 | N24: =(F24-F$11)/F$11*100 -> -100 | O24: =(G24-G$11)/G$11*100 -> -100 | Q24: long | R24: stiff | S24: =(H24-H$11)/H$11*100 -> 14.357342

Sheet 2.7 grid
Z5: lengths | AA5: 0.0718 | AB5: =AC5/2 -> 0.14345 | AC5: 0.2869 | AD5: 0.4305 | AE5: 0.5741
Z6: stiff | AA6: 30 | AB6: 60 | AC6: 120 | AD6: 180 | AE6: 240
B7: metabolic values | I7: percent savings | Q7: Bottom of the bowl savings. | U7: Table
B8: time | C8: 0.568 | D8: 0.608 | E8: 0.648 | F8: 0.6835 | G8: 0.7235 | I8: time | L8: 0.608 | M8: 0.648 | N8: 0.6835 | O8: 0.7235
V9: Percent change Natural to Exotendon 2.7 m/s | X9: exotendon length (m)
H10: minimums | X10: l=0.0718 | Y10: l=0.1435 | Z10: l=0.2869 | AA10: l=0.4305 | AB10: l=0.5741
B11: natural | D11: 11.731276 | E11: 11.5224 | F11: 11.39893 | G11: 12.445986 | H11: =F11 -> 11.39893 | J11: natural | R11: natural | V11: exotendon stiffness (N/m) | W11: 30 | X11: -1.8756673 | Y11: -2.4502475 | Z11: -0.16209416 | AA11: 0.088245125
W12: 60 | X12: -4.0921209 | Y12: -3.6116109 | Z12: -2.1836874 | AA12: -0.82156834
A13: length | B13: stiff | I13: length | J13: stiff | Q13: length | R13: stiff | W13: 120 | X13: -5.0363148 | Y13: -5.8848769 | Z13: -4.9471924 | AA13: -1.9417963
A14: nom | B14: compliant2 | D14: 11.553375 | E14: 11.380453 | F14: 11.207462 | G14: 12.250952 | H14: =E14 -> 11.380453 | I14: nom | J14: compliant2 | L14: =(D14-D$11)/D$11*100 -> -1.5164676 | M14: =(E14-E$11)/E$11*100 -> -1.2319222 | N14: =(F14-F$11)/F$11*100 -> -1.6797015 | O14: =(G14-G$11)/G$11*100 -> -1.5670434 | Q14: nom | R14: compliant2 | S14: =(H14-H$11)/H$11*100 -> -0.16209416 | W14: 180 | X14: 0.86873066 | Y14: -3.4834585 | Z14: -6.5935575 | AA14: -3.746799
A15: nom | B15: compliant | D15: 11.348456 | E15: 11.150013 | F15: 10.980339 | G15: 12.084496 | H15: =E15 -> 11.150013 | I15: nom | J15: compliant | L15: =(D15-D$11)/D$11*100 -> -3.2632426 | M15: =(E15-E$11)/E$11*100 -> -3.2318527 | N15: =(F15-F$11)/F$11*100 -> -3.6721955 | O15: =(G15-G$11)/G$11*100 -> -2.9044706 | Q15: nom | R15: compliant | S15: =(H15-H$11)/H$11*100 -> -2.1836874 | W15: 240 | X15: 9.5504227 | Y15: 2.8739101 | Z15: -6.5019962 | AA15: -5.269056 | AB15: 0.4204342
A16: nom | B16: nom | D16: 11.026181 | E16: 10.835003 | F16: 10.698467 | G16: 11.967513 | H16: =E16 -> 10.835003 | I16: nom | J16: nom | L16: =(D16-D$11)/D$11*100 -> -6.0103863 | M16: =(E16-E$11)/E$11*100 -> -5.965745 | N16: =(F16-F$11)/F$11*100 -> -6.144989 | O16: =(G16-G$11)/G$11*100 -> -3.8443961 | Q16: nom | R16: nom | S16: =(H16-H$11)/H$11*100 -> -4.9471924
A17: nom | B17: stiff | D17: 10.774253 | E17: 10.647335 | F17: 10.719427 | G17: 12.190057 | H17: =E17 -> 10.647335 | I17: nom | J17: stiff | L17: =(D17-D$11)/D$11*100 -> -8.1578764 | M17: =(E17-E$11)/E$11*100 -> -7.5944682 | N17: =(F17-F$11)/F$11*100 -> -5.9611121 | O17: =(G17-G$11)/G$11*100 -> -2.0563176 | Q17: nom | R17: stiff | S17: =(H17-H$11)/H$11*100 -> -6.5935575
A18: nom | B18: stiff2 | D18: 10.640896 | E18: 10.657772 | F18: 10.995718 | G18: 12.55104 | H18: =E18 -> 10.657772 | I18: nom | J18: stiff2 | L18: =(D18-D$11)/D$11*100 -> -9.2946411 | M18: =(E18-E$11)/E$11*100 -> -7.5038881 | N18: =(F18-F$11)/F$11*100 -> -3.5372794 | O18: =(G18-G$11)/G$11*100 -> 0.84407937 | Q18: nom | R18: stiff2 | S18: =(H18-H$11)/H$11*100 -> -6.5019962
A20: short | B20: compliant2 | D20: 12.186453 | E20: 11.119628 | F20: 11.233163 | G20: 11.447347 | H20: =E20 -> 11.119628 | I20: short | J20: compliant2 | L20: =(D20-D$11)/D$11*100 -> 3.8800298 | M20: =(E20-E$11)/E$11*100 -> -3.4955565 | N20: =(F20-F$11)/F$11*100 -> -1.454233 | O20: =(G20-G$11)/G$11*100 -> -8.0237837 | Q20: short | R20: compliant2 | S20: =(H20-H$11)/H$11*100 -> -2.4502475
A21: short | B21: compliant | D21: 11.203635 | E21: 10.987245 | F21: 10.851474 | G21: 12.022994 | H21: =E21 -> 10.987245 | I21: short | J21: compliant | L21: =(D21-D$11)/D$11*100 -> -4.497729 | M21: =(E21-E$11)/E$11*100 -> -4.6444751 | N21: =(F21-F$11)/F$11*100 -> -4.8026964 | O21: =(G21-G$11)/G$11*100 -> -3.3986219 | Q21: short | R21: compliant | S21: =(H21-H$11)/H$11*100 -> -3.6116109
A22: short | B22: nom | D22: 10.888108 | E22: 10.728117 | F22: 10.767687 | G22: 12.226369 | H22: =E22 -> 10.728117 | I22: short | J22: nom | L22: =(D22-D$11)/D$11*100 -> -7.1873511 | M22: =(E22-E$11)/E$11*100 -> -6.8933816 | N22: =(F22-F$11)/F$11*100 -> -5.5377391 | O22: =(G22-G$11)/G$11*100 -> -1.7645609 | Q22: short | R22: nom | S22: =(H22-H$11)/H$11*100 -> -5.8848769
A23: short | B23: stiff | D23: 10.838987 | E23: 11.001853 | F23: 11.405944 | G23: 13.003933 | H23: =E23 -> 11.001853 | I23: short | J23: stiff | L23: =(D23-D$11)/D$11*100 -> -7.6060695 | M23: =(E23-E$11)/E$11*100 -> -4.517696 | N23: =(F23-F$11)/F$11*100 -> 0.061532091 | O23: =(G23-G$11)/G$11*100 -> 4.4829474 | Q23: short | R23: stiff | S23: =(H23-H$11)/H$11*100 -> -3.4834585
A24: short | B24: stiff2 | D24: 11.189222 | E24: 11.726525 | F24: 12.15562 | G24: 13.923594 | H24: =E24 -> 11.726525 | I24: short | J24: stiff2 | L24: =(D24-D$11)/D$11*100 -> -4.6205886 | M24: =(E24-E$11)/E$11*100 -> 1.7715493 | N24: =(F24-F$11)/F$11*100 -> 6.6382546 | O24: =(G24-G$11)/G$11*100 -> 11.872165 | Q24: short | R24: stiff2 | S24: =(H24-H$11)/H$11*100 -> 2.8739101
A26: long | B26: compliant2 | D26: 11.643253 | E26: 11.408989 | F26: 11.265032 | G26: 12.334257 | H26: =E26 -> 11.408989 | I26: long | J26: compliant2 | L26: =(D26-D$11)/D$11*100 -> -0.75032759 | M26: =(E26-E$11)/E$11*100 -> -0.98426543 | N26: =(F26-F$11)/F$11*100 -> -1.1746541 | O26: =(G26-G$11)/G$11*100 -> -0.89771112 | Q26: long | R26: compliant2 | S26: =(H26-H$11)/H$11*100 -> 0.088245125
A27: long | B27: compliant | D27: 11.572773 | E27: 11.30528 | F27: 11.21571 | G27: 12.247591 | H27: =E27 -> 11.30528 | I27: long | J27: compliant | L27: =(D27-D$11)/D$11*100 -> -1.3511147 | M27: =(E27-E$11)/E$11*100 -> -1.8843297 | N27: =(F27-F$11)/F$11*100 -> -1.6073438 | O27: =(G27-G$11)/G$11*100 -> -1.5940481 | Q27: long | R27: compliant | S27: =(H27-H$11)/H$11*100 -> -0.82156834
A28: long | B28: nom | D28: 11.385911 | E28: 11.177586 | F28: 10.966885 | G28: 12.043964 | H28: =E28 -> 11.177586 | I28: long | J28: nom | L28: =(D28-D$11)/D$11*100 -> -2.9439679 | M28: =(E28-E$11)/E$11*100 -> -2.9925536 | N28: =(F28-F$11)/F$11*100 -> -3.7902242 | O28: =(G28-G$11)/G$11*100 -> -3.2301338 | Q28: long | R28: nom | S28: =(H28-H$11)/H$11*100 -> -1.9417963
A29: long | B29: stiff | D29: 11.221195 | E29: 10.971835 | F29: 10.778619 | G29: 11.939745 | H29: =E29 -> 10.971835 | I29: long | J29: stiff | L29: =(D29-D$11)/D$11*100 -> -4.3480436 | M29: =(E29-E$11)/E$11*100 -> -4.7782146 | N29: =(F29-F$11)/F$11*100 -> -5.4418353 | O29: =(G29-G$11)/G$11*100 -> -4.0675042 | Q29: long | R29: stiff | S29: =(H29-H$11)/H$11*100 -> -3.746799
... A36: short2 | B36: stiff2 | D36: 11.816176 | E36: 12.487576 | F36: 12.949939 | G36: 14.728507 | H36: =E36 -> 12.487576 | I36: short2 | J36: stiff2 | L36: =(D36-D$11)/D$11*100 -> 0.72370644 | M36: =(E36-E$11)/E$11*100 -> 8.3765188 | N36: =(F36-F$11)/F$11*100 -> 13.606619 | O36: =(G36-G$11)/G$11*100 -> 18.339415 | Q36: short2 | R36: stiff2 | S36: =(H36-H$11)/H$11*100 -> 9.5504227
A38: long2 | B38: compliant2 | H38: =E38 -> 0 | I38: long2 | J38: compliant2 | L38: =(D38-D$11)/D$11*100 -> -100 | M38: =(E38-E$11)/E$11*100 -> -100 | N38: =(F38-F$11)/F$11*100 -> -100 | O38: =(G38-G$11)/G$11*100 -> -100 | Q38: long2 | R38: compliant2 | S38: =(H38-H$11)/H$11*100 -> -100
A39: long2 | B39: compliant | H39: =E39 -> 0 | I39: long2 | J39: compliant | L39: =(D39-D$11)/D$11*100 -> -100 | M39: =(E39-E$11)/E$11*100 -> -100 | N39: =(F39-F$11)/F$11*100 -> -100 | O39: =(G39-G$11)/G$11*100 -> -100 | Q39: long2 | R39: compliant | S39: =(H39-H$11)/H$11*100 -> -100
A40: long2 | B40: nom | H40: =E40 -> 0 | I40: long2 | J40: nom | L40: =(D40-D$11)/D$11*100 -> -100 | M40: =(E40-E$11)/E$11*100 -> -100 | N40: =(F40-F$11)/F$11*100 -> -100 | O40: =(G40-G$11)/G$11*100 -> -100 | Q40: long2 | R40: nom | S40: =(H40-H$11)/H$11*100 -> -100
A41: long2 | B41: stiff | H41: =E41 -> 0 | I41: long2 | J41: stiff | L41: =(D41-D$11)/D$11*100 -> -100 | M41: =(E41-E$11)/E$11*100 -> -100 | N41: =(F41-F$11)/F$11*100 -> -100 | O41: =(G41-G$11)/G$11*100 -> -100 | Q41: long2 | R41: stiff | S41: =(H41-H$11)/H$11*100 -> -100
A42: long2 | B42: stiff2 | D42: 11.647097 | E42: 11.446855 | F42: 11.816176 | G42: 12.176914 | H42: =E42 -> 11.446855 | I42: long2 | J42: stiff2 | L42: =(D42-D$11)/D$11*100 -> -0.71756048 | M42: =(E42-E$11)/E$11*100 -> -0.65563598 | N42: =(F42-F$11)/F$11*100 -> 3.6603962 | O42: =(G42-G$11)/G$11*100 -> -2.1619179 | Q42: long2 | R42: stiff2 | S42: =(H42-H$11)/H$11*100 -> 0.4204342
H45: =E45 -> 0
H46: =E46 -> 0
H47: =E47 -> 0
H48: =E48 -> 0
H49: =E49 -> 0
H50: =E50 -> 0
H51: =E51 -> 0

Sheet 4 grid
Z5: lengths | AA5: 0.0718 | AB5: =AC5/2 -> 0.14345 | AC5: 0.2869 | AD5: 0.4305 | AE5: 0.5741
Z6: stiff | AA6: 30 | AB6: 60 | AC6: 120 | AD6: 180 | AE6: 240
B7: metabolic values | I7: percent savings | Q7: Bottom of the bowl savings. | U7: Table
B8: time | C8: 0.564 | D8: 0.604 | E8: 0.644 | F8: 0.684 | G8: 0.724 | I8: time | L8: 0.608 | M8: 0.648 | N8: 0.6835 | O8: 0.7235
V9: Percent change Natural to Exotendon 4.0 m/s | X9: exotendon length (m)
H10: minimums | X10: l=0.0718 | Y10: l=0.1435 | Z10: l=0.2869 | AA10: l=0.4305 | AB10: l=0.5741
B11: natural | D11: 17.968925 | E11: 17.407076 | F11: 17.503123 | G11: 19.048659 | H11: =F11 -> 17.503123 | J11: natural | R11: natural | V11: exotendon stiffness (N/m) | W11: 30 | X11: -7.2819119 | Y11: -6.6979818 | Z11: -5.2920156 | AA11: -4.160886
W12: 60 | X12: -11.898831 | Y12: -10.94976 | Z12: -8.7608194 | AA12: -6.6480879
A13: length | B13: stiff | I13: length | J13: stiff | Q13: length | R13: stiff | W13: 120 | X13: -16.388984 | Y13: -16.917724 | Z13: -15.224237 | AA13: -11.983576
A14: nom | B14: compliant2 | D14: 16.769624 | E14: 16.576855 | F14: 17.262923 | G14: 18.412359 | H14: =E14 -> 16.576855 | I14: nom | J14: compliant2 | L14: =(D14-D$11)/D$11*100 -> -6.6743058 | M14: =(E14-E$11)/E$11*100 -> -4.7694455 | N14: =(F14-F$11)/F$11*100 -> -1.3723265 | O14: =(G14-G$11)/G$11*100 -> -3.3403926 | Q14: nom | R14: compliant2 | S14: =(H14-H$11)/H$11*100 -> -5.2920156 | W14: 180 | X14: -10.773934 | Y14: -14.520209 | Z14: -17.870405 | AA14: -16.266543
A15: nom | B15: compliant | D15: 16.285982 | E15: 15.969706 | F15: 17.337683 | G15: 17.790658 | H15: =E15 -> 15.969706 | I15: nom | J15: compliant | L15: =(D15-D$11)/D$11*100 -> -9.3658524 | M15: =(E15-E$11)/E$11*100 -> -8.2573891 | N15: =(F15-F$11)/F$11*100 -> -0.94520275 | O15: =(G15-G$11)/G$11*100 -> -6.6041447 | Q15: nom | R15: compliant | S15: =(H15-H$11)/H$11*100 -> -8.7608194 | W15: 240 | X15: 2.4567273 | Y15: -4.7745594 | Z15: -15.983399 | AA15: -18.542902 | AB15: -14.669382
A16: nom | B16: nom | D16: 15.281987 | E16: 14.838406 | F16: 16.168668 | G16: 17.208356 | H16: =E16 -> 14.838406 | I16: nom | J16: nom | L16: =(D16-D$11)/D$11*100 -> -14.953248 | M16: =(E16-E$11)/E$11*100 -> -14.75647 | N16: =(F16-F$11)/F$11*100 -> -7.6240966 | O16: =(G16-G$11)/G$11*100 -> -9.6610633 | Q16: nom | R16: nom | S16: =(H16-H$11)/H$11*100 -> -15.224237
A17: nom | B17: stiff | D17: 14.520813 | E17: 14.375244 | F17: 15.989204 | G17: 17.618579 | H17: =E17 -> 14.375244 | I17: nom | J17: stiff | L17: =(D17-D$11)/D$11*100 -> -19.189306 | M17: =(E17-E$11)/E$11*100 -> -17.417239 | N17: =(F17-F$11)/F$11*100 -> -8.6494222 | O17: =(G17-G$11)/G$11*100 -> -7.5075101 | Q17: nom | R17: stiff | S17: =(H17-H$11)/H$11*100 -> -17.870405
A18: nom | B18: stiff2 | D18: 14.2675 | E18: 14.705529 | F18: 16.976647 | G18: 18.947458 | H18: =E18 -> 14.705529 | I18: nom | J18: stiff2 | L18: =(D18-D$11)/D$11*100 -> -20.599034 | M18: =(E18-E$11)/E$11*100 -> -15.519821 | N18: =(F18-F$11)/F$11*100 -> -3.0078975 | O18: =(G18-G$11)/G$11*100 -> -0.53127624 | Q18: nom | R18: stiff2 | S18: =(H18-H$11)/H$11*100 -> -15.983399
A20: short | B20: compliant2 | D20: 16.49467 | E20: 16.330767 | F20: 17.611142 | G20: 18.241536 | H20: =E20 -> 16.330767 | I20: short | J20: compliant2 | L20: =(D20-D$11)/D$11*100 -> -8.2044697 | M20: =(E20-E$11)/E$11*100 -> -6.1831694 | N20: =(F20-F$11)/F$11*100 -> 0.6171413 | O20: =(G20-G$11)/G$11*100 -> -4.2371644 | Q20: short | R20: compliant2 | S20: =(H20-H$11)/H$11*100 -> -6.6979818
A21: short | B21: compliant | D21: 15.947742 | E21: 15.586573 | F21: 16.822281 | G21: 17.514571 | H21: =E21 -> 15.586573 | I21: short | J21: compliant | L21: =(D21-D$11)/D$11*100 -> -11.248213 | M21: =(E21-E$11)/E$11*100 -> -10.458408 | N21: =(F21-F$11)/F$11*100 -> -3.8898315 | O21: =(G21-G$11)/G$11*100 -> -8.0535223 | Q21: short | R21: compliant | S21: =(H21-H$11)/H$11*100 -> -10.94976
A22: short | B22: nom | D22: 14.824421 | E22: 14.541993 | F22: 16.129129 | G22: 17.346248 | H22: =E22 -> 14.541993 | I22: short | J22: nom | L22: =(D22-D$11)/D$11*100 -> -17.499678 | M22: =(E22-E$11)/E$11*100 -> -16.459301 | N22: =(F22-F$11)/F$11*100 -> -7.8499934 | O22: =(G22-G$11)/G$11*100 -> -8.9371698 | Q22: short | R22: nom | S22: =(H22-H$11)/H$11*100 -> -16.917724
A23: short | B23: stiff | D23: 14.545803 | E23: 14.961633 | F23: 17.169218 | G23: 18.960162 | H23: =E23 -> 14.961633 | I23: short | J23: stiff | L23: =(D23-D$11)/D$11*100 -> -19.050233 | M23: =(E23-E$11)/E$11*100 -> -14.048557 | N23: =(F23-F$11)/F$11*100 -> -1.9076881 | O23: =(G23-G$11)/G$11*100 -> -0.46458388 | Q23: short | R23: stiff | S23: =(H23-H$11)/H$11*100 -> -14.520209
A24: short | B24: stiff2 | D24: 15.058503 | E24: 16.667426 | F24: 19.077895 | G24: 21.091202 | H24: =E24 -> 16.667426 | I24: short | J24: stiff2 | L24: =(D24-D$11)/D$11*100 -> -16.196973 | M24: =(E24-E$11)/E$11*100 -> -4.2491341 | N24: =(F24-F$11)/F$11*100 -> 8.9970915 | O24: =(G24-G$11)/G$11*100 -> 10.722765 | Q24: short | R24: stiff2 | S24: =(H24-H$11)/H$11*100 -> -4.7745594
A26: long | B26: compliant2 | D26: 16.965086 | E26: 16.774838 | F26: 17.270606 | G26: 18.57538 | H26: =E26 -> 16.774838 | I26: long | J26: compliant2 | L26: =(D26-D$11)/D$11*100 -> -5.5865279 | M26: =(E26-E$11)/E$11*100 -> -3.6320747 | N26: =(F26-F$11)/F$11*100 -> -1.3284315 | O26: =(G26-G$11)/G$11*100 -> -2.4845791 | Q26: long | R26: compliant2 | S26: =(H26-H$11)/H$11*100 -> -4.160886
A27: long | B27: compliant | D27: 16.642357 | E27: 16.3395 | F27: 17.728614 | G27: 18.130882 | H27: =E27 -> 16.3395 | I27: long | J27: compliant | L27: =(D27-D$11)/D$11*100 -> -7.3825674 | M27: =(E27-E$11)/E$11*100 -> -6.1330002 | N27: =(F27-F$11)/F$11*100 -> 1.2882901 | O27: =(G27-G$11)/G$11*100 -> -4.8180662 | Q27: long | R27: compliant | S27: =(H27-H$11)/H$11*100 -> -6.6480879
A28: long | B28: nom | D28: 15.954845 | E28: 15.405623 | F28: 16.527564 | G28: 17.33401 | H28: =E28 -> 15.405623 | I28: long | J28: nom | L28: =(D28-D$11)/D$11*100 -> -11.208684 | M28: =(E28-E$11)/E$11*100 -> -11.497928 | N28: =(F28-F$11)/F$11*100 -> -5.5736282 | O28: =(G28-G$11)/G$11*100 -> -9.0014158 | Q28: long | R28: nom | S28: =(H28-H$11)/H$11*100 -> -11.983576
A29: long | B29: stiff | D29: 15.143201 | E29: 14.65597 | F29: 15.960575 | G29: 16.994731 | H29: =E29 -> 14.65597 | I29: long | J29: stiff | L29: =(D29-D$11)/D$11*100 -> -15.725615 | M29: =(E29-E$11)/E$11*100 -> -15.804527 | N29: =(F29-F$11)/F$11*100 -> -8.8129873 | O29: =(G29-G$11)/G$11*100 -> -10.782533 | Q29: long | R29: stiff | S29: =(H29-H$11)/H$11*100 -> -16.266543
... A36: short2 | B36: stiff2 | D36: 16.118039 | E36: 17.933127 | F36: 20.352262 | G36: 22.391478 | H36: =E36 -> 17.933127 | I36: short2 | J36: stiff2 | L36: =(D36-D$11)/D$11*100 -> -10.300483 | M36: =(E36-E$11)/E$11*100 -> 3.0220526 | N36: =(F36-F$11)/F$11*100 -> 16.277889 | O36: =(G36-G$11)/G$11*100 -> 17.548842 | Q36: short2 | R36: stiff2 | S36: =(H36-H$11)/H$11*100 -> 2.4567273
A38: long2 | B38: compliant2 | H38: =E38 -> 0 | I38: long2 | J38: compliant2 | L38: =(D38-D$11)/D$11*100 -> -100 | M38: =(E38-E$11)/E$11*100 -> -100 | N38: =(F38-F$11)/F$11*100 -> -100 | O38: =(G38-G$11)/G$11*100 -> -100 | Q38: long2 | R38: compliant2 | S38: =(H38-H$11)/H$11*100 -> -100
A39: long2 | B39: compliant | H39: =E39 -> 0 | I39: long2 | J39: compliant | L39: =(D39-D$11)/D$11*100 -> -100 | M39: =(E39-E$11)/E$11*100 -> -100 | N39: =(F39-F$11)/F$11*100 -> -100 | O39: =(G39-G$11)/G$11*100 -> -100 | Q39: long2 | R39: compliant | S39: =(H39-H$11)/H$11*100 -> -100
A40: long2 | B40: nom | H40: =E40 -> 0 | I40: long2 | J40: nom | L40: =(D40-D$11)/D$11*100 -> -100 | M40: =(E40-E$11)/E$11*100 -> -100 | N40: =(F40-F$11)/F$11*100 -> -100 | O40: =(G40-G$11)/G$11*100 -> -100 | Q40: long2 | R40: nom | S40: =(H40-H$11)/H$11*100 -> -100
A41: long2 | B41: stiff | H41: =E41 -> 0 | I41: long2 | J41: stiff | L41: =(D41-D$11)/D$11*100 -> -100 | M41: =(E41-E$11)/E$11*100 -> -100 | N41: =(F41-F$11)/F$11*100 -> -100 | O41: =(G41-G$11)/G$11*100 -> -100 | Q41: long2 | R41: stiff | S41: =(H41-H$11)/H$11*100 -> -100
A42: long2 | B42: stiff2 | D42: 15.546004 | E42: 14.935523 | F42: 15.983874 | G42: 17.047042 | H42: =E42 -> 14.935523 | I42: long2 | J42: stiff2 | L42: =(D42-D$11)/D$11*100 -> -13.483951 | M42: =(E42-E$11)/E$11*100 -> -14.198554 | N42: =(F42-F$11)/F$11*100 -> -8.6798739 | O42: =(G42-G$11)/G$11*100 -> -10.507916 | Q42: long2 | R42: stiff2 | S42: =(H42-H$11)/H$11*100 -> -14.669382
H45: =E45 -> 0
H46: =E46 -> 0
H47: =E47 -> 0
H48: =E48 -> 0
H49: =E49 -> 0
H50: =E50 -> 0
H51: =E51 -> 0

Sheet 2.7 grid_figure
A1: ='2.7 grid'!$V$9 -> Percent change Natural to Exotendon 2.7 m/s | C1: ='2.7 grid'!$X$9 -> exotendon length (m)
C2: ='2.7 grid'!X10 -> l=0.0718 | D2: ='2.7 grid'!Y10 -> l=0.1435 | E2: ='2.7 grid'!Z10 -> l=0.2869 | F2: ='2.7 grid'!AA10 -> l=0.4305
A3: ='2.7 grid'!$V$11 -> exotendon stiffness (N/m) | B3: ='2.7 grid'!W11 -> 30 | C3: ='2.7 grid'!X11 -> -1.8756673 | D3: ='2.7 grid'!Y11 -> -2.4502475 | E3: ='2.7 grid'!Z11 -> -0.16209416 | F3: ='2.7 grid'!AA11 -> 0.088245125
B4: ='2.7 grid'!W12 -> 60 | C4: ='2.7 grid'!X12 -> -4.0921209 | D4: ='2.7 grid'!Y12 -> -3.6116109 | E4: ='2.7 grid'!Z12 -> -2.1836874 | F4: ='2.7 grid'!AA12 -> -0.82156834
B5: ='2.7 grid'!W13 -> 120 | C5: ='2.7 grid'!X13 -> -5.0363148 | D5: ='2.7 grid'!Y13 -> -5.8848769 | E5: ='2.7 grid'!Z13 -> -4.9471924 | F5: ='2.7 grid'!AA13 -> -1.9417963
B6: ='2.7 grid'!W14 -> 180 | C6: ='2.7 grid'!X14 -> 0.86873066 | D6: ='2.7 grid'!Y14 -> -3.4834585 | E6: ='2.7 grid'!Z14 -> -6.5935575 | F6: ='2.7 grid'!AA14 -> -3.746799
B7: ='2.7 grid'!W15 -> 240 | C7: ='2.7 grid'!X15 -> 9.5504227 | D7: ='2.7 grid'!Y15 -> 2.8739101 | E7: ='2.7 grid'!Z15 -> -6.5019962 | F7: ='2.7 grid'!AA15 -> -5.269056

Sheet 2.7 grid_figure (2)
A1: stiffness | B1: 0.0718 | C1: 0.1435 | D1: 0.2869 | E1: 0.4305
A2: ='2.7 grid'!W11 -> 30 | B2: ='2.7 grid'!X11 -> -1.8756673 | C2: ='2.7 grid'!Y11 -> -2.4502475 | D2: ='2.7 grid'!Z11 -> -0.16209416 | E2: ='2.7 grid'!AA11 -> 0.088245125
A3: ='2.7 grid'!W12 -> 60 | B3: ='2.7 grid'!X12 -> -4.0921209 | C3: ='2.7 grid'!Y12 -> -3.6116109 | D3: ='2.7 grid'!Z12 -> -2.1836874 | E3: ='2.7 grid'!AA12 -> -0.82156834
A4: ='2.7 grid'!W13 -> 120 | B4: ='2.7 grid'!X13 -> -5.0363148 | C4: ='2.7 grid'!Y13 -> -5.8848769 | D4: ='2.7 grid'!Z13 -> -4.9471924 | E4: ='2.7 grid'!AA13 -> -1.9417963
A5: ='2.7 grid'!W14 -> 180 | B5: ='2.7 grid'!X14 -> 0.86873066 | C5: ='2.7 grid'!Y14 -> -3.4834585 | D5: ='2.7 grid'!Z14 -> -6.5935575 | E5: ='2.7 grid'!AA14 -> -3.746799
A6: ='2.7 grid'!W15 -> 240 | B6: ='2.7 grid'!X15 -> 9.5504227 | C6: ='2.7 grid'!Y15 -> 2.8739101 | D6: ='2.7 grid'!Z15 -> -6.5019962 | E6: ='2.7 grid'!AA15 -> -5.269056

Sheet 4 grid_figure
A1: ='4 grid'!$V$9 -> Percent change Natural to Exotendon 4.0 m/s | C1: ='4 grid'!$X$9 -> exotendon length (m)
C2: ='4 grid'!X10 -> l=0.0718 | D2: ='4 grid'!Y10 -> l=0.1435 | E2: ='4 grid'!Z10 -> l=0.2869 | F2: ='4 grid'!AA10 -> l=0.4305
A3: ='4 grid'!$V$11 -> exotendon stiffness (N/m) | B3: ='4 grid'!W11 -> 30 | C3: ='4 grid'!X11 -> -7.2819119 | D3: ='4 grid'!Y11 -> -6.6979818 | E3: ='4 grid'!Z11 -> -5.2920156 | F3: ='4 grid'!AA11 -> -4.160886
B4: ='4 grid'!W12 -> 60 | C4: ='4 grid'!X12 -> -11.898831 | D4: ='4 grid'!Y12 -> -10.94976 | E4: ='4 grid'!Z12 -> -8.7608194 | F4: ='4 grid'!AA12 -> -6.6480879
B5: ='4 grid'!W13 -> 120 | C5: ='4 grid'!X13 -> -16.388984 | D5: ='4 grid'!Y13 -> -16.917724 | E5: ='4 grid'!Z13 -> -15.224237 | F5: ='4 grid'!AA13 -> -11.983576
B6: ='4 grid'!W14 -> 180 | C6: ='4 grid'!X14 -> -10.773934 | D6: ='4 grid'!Y14 -> -14.520209 | E6: ='4 grid'!Z14 -> -17.870405 | F6: ='4 grid'!AA14 -> -16.266543
B7: ='4 grid'!W15 -> 240 | C7: ='4 grid'!X15 -> 2.4567273 | D7: ='4 grid'!Y15 -> -4.7745594 | E7: ='4 grid'!Z15 -> -15.983399 | F7: ='4 grid'!AA15 -> -18.542902

Sheet 4 grid_figure (2)
A1: stiffness | B1: 0.0718 | C1: 0.1435 | D1: 0.2869 | E1: 0.4305
A2: ='4 grid'!W11 -> 30 | B2: ='4 grid'!X11 -> -7.2819119 | C2: ='4 grid'!Y11 -> -6.6979818 | D2: ='4 grid'!Z11 -> -5.2920156 | E2: ='4 grid'!AA11 -> -4.160886
A3: ='4 grid'!W12 -> 60 | B3: ='4 grid'!X12 -> -11.898831 | C3: ='4 grid'!Y12 -> -10.94976 | D3: ='4 grid'!Z12 -> -8.7608194 | E3: ='4 grid'!AA12 -> -6.6480879
A4: ='4 grid'!W13 -> 120 | B4: ='4 grid'!X13 -> -16.388984 | C4: ='4 grid'!Y13 -> -16.917724 | D4: ='4 grid'!Z13 -> -15.224237 | E4: ='4 grid'!AA13 -> -11.983576
A5: ='4 grid'!W14 -> 180 | B5: ='4 grid'!X14 -> -10.773934 | C5: ='4 grid'!Y14 -> -14.520209 | D5: ='4 grid'!Z14 -> -17.870405 | E5: ='4 grid'!AA14 -> -16.266543
A6: ='4 grid'!W15 -> 240 | B6: ='4 grid'!X15 -> 2.4567273 | C6: ='4 grid'!Y15 -> -4.7745594 | D6: ='4 grid'!Z15 -> -15.983399 | E6: ='4 grid'!AA15 -> -18.542902

Sheet 4 grid 12.24
Z5: lengths | AA5: 0.0718 | AB5: =AC5/2 -> 0.14345 | AC5: 0.2869 | AD5: 0.4305 | AE5: 0.5741
Z6: stiff | AA6: 30 | AB6: 60 | AC6: 120 | AD6: 180 | AE6: 240
B7: metabolic values | I7: percent savings | Q7: Bottom of the bowl savings. | U7: Table
B8: time | C8: 0.564 | D8: 0.604 | E8: 0.644 | F8: 0.684 | G8: 0.724 | I8: time | L8: 0.608 | M8: 0.648 | N8: 0.6835 | O8: 0.7235
V9: Percent change Natural to Exotendon 4.0 m/s | X9: exotendon length (m)
H10: minimums | X10: l=0.0718 | Y10: l=0.1435 | Z10: l=0.2869 | AA10: l=0.4305 | AB10: l=0.5741
B11: natural | D11: 15.043569 | E11: 14.700311 | F11: 16.002903 | G11: 16.193719 | H11: =F11 -> 16.002903 | J11: natural | R11: natural | V11: exotendon stiffness (N/m) | W11: 30
W12: 60
A13: length | B13: stiff | I13: length | J13: stiff | Q13: length | R13: stiff | W13: 120
A14: nom | B14: compliant2 | D14: 14.635444 | E14: 14.420223 | F14: 15.439938 | G14: 15.673591 | H14: =E14 -> 14.420223 | I14: nom | J14: compliant2 | L14: =(D14-D$11)/D$11*100 -> -2.7129533 | M14: =(E14-E$11)/E$11*100 -> -1.9053202 | N14: =(F14-F$11)/F$11*100 -> -3.517893 | O14: =(G14-G$11)/G$11*100 -> -3.211912 | Q14: nom | R14: compliant2 | S14: =(H14-H$11)/H$11*100 -> -9.8899556 | W14: 180
A15: nom | B15: compliant | D15: 14.153262 | E15: 13.769769 | F15: 14.94606 | G15: 15.446721 | H15: =E15 -> 13.769769 | I15: nom | J15: compliant | L15: =(D15-D$11)/D$11*100 -> -5.91819 | M15: =(E15-E$11)/E$11*100 -> -6.3300838 | N15: =(F15-F$11)/F$11*100 -> -6.6040705 | O15: =(G15-G$11)/G$11*100 -> -4.6128873 | Q15: nom | R15: compliant | S15: =(H15-H$11)/H$11*100 -> -13.954556 | W15: 240
A16: nom | B16: nom | D16: 13.420841 | E16: 13.045504 | F16: 14.34627 | G16: 15.514805 | H16: =E16 -> 13.045504 | I16: nom | J16: nom | L16: =(D16-D$11)/D$11*100 -> -10.786855 | M16: =(E16-E$11)/E$11*100 -> -11.256952 | N16: =(F16-F$11)/F$11*100 -> -10.352078 | O16: =(G16-G$11)/G$11*100 -> -4.1924526 | Q16: nom | R16: nom | S16: =(H16-H$11)/H$11*100 -> -18.480391
A17: nom | B17: stiff | D17: 13.004188 | E17: 13.150717 | F17: 15.011099 | G17: 16.537302 | H17: =E17 -> 13.150717 | I17: nom | J17: stiff | L17: =(D17-D$11)/D$11*100 -> -13.556497 | M17: =(E17-E$11)/E$11*100 -> -10.541233 | N17: =(F17-F$11)/F$11*100 -> -6.1976505 | O17: =(G17-G$11)/G$11*100 -> 2.1217053 | Q17: nom | R17: stiff | S17: =(H17-H$11)/H$11*100 -> -17.822929
A18: nom | B18: stiff2 | D18: 13.024088 | E18: 14.041384 | F18: 16.096648 | G18: 17.844043 | H18: =E18 -> 14.041384 | I18: nom | J18: stiff2 | L18: =(D18-D$11)/D$11*100 -> -13.424215 | M18: =(E18-E$11)/E$11*100 -> -4.4824018 | N18: =(F18-F$11)/F$11*100 -> 0.58579996 | O18: =(G18-G$11)/G$11*100 -> 10.191136 | Q18: nom | R18: stiff2 | S18: =(H18-H$11)/H$11*100 -> -12.25727
A20: short | B20: compliant2 | D20: 14.434096 | E20: 14.254329 | F20: 15.205894 | G20: 15.689239 | H20: =E20 -> 14.254329 | I20: short | J20: compliant2 | L20: =(D20-D$11)/D$11*100 -> -4.0513857 | M20: =(E20-E$11)/E$11*100 -> -3.033827 | N20: =(F20-F$11)/F$11*100 -> -4.9804026 | O20: =(G20-G$11)/G$11*100 -> -3.1152819 | Q20: short | R20: compliant2 | S20: =(H20-H$11)/H$11*100 -> -10.926605
A21: short | B21: compliant | D21: 13.911338 | E21: 13.416015 | F21: 14.561228 | G21: 15.203208 | H21: =E21 -> 13.416015 | I21: short | J21: compliant | L21: =(D21-D$11)/D$11*100 -> -7.5263456 | M21: =(E21-E$11)/E$11*100 -> -8.7365226 | N21: =(F21-F$11)/F$11*100 -> -9.0088342 | O21: =(G21-G$11)/G$11*100 -> -6.116637 | Q21: short | R21: compliant | S21: =(H21-H$11)/H$11*100 -> -16.165117
A22: short | B22: nom | D22: 13.10949 | E22: 13.025745 | F22: 14.60103 | H22: =E22 -> 13.025745 | I22: short | J22: nom | L22: =(D22-D$11)/D$11*100 -> -12.856517 | M22: =(E22-E$11)/E$11*100 -> -11.391364 | N22: =(F22-F$11)/F$11*100 -> -8.7601168 | O22: =(G22-G$11)/G$11*100 -> -100 | Q22: short | R22: nom | S22: =(H22-H$11)/H$11*100 -> -18.603862
A23: short | B23: stiff | D23: 13.146532 | E23: 14.095967 | F23: 15.990974 | G23: 17.669705 | H23: =E23 -> 14.095967 | I23: short | J23: stiff | L23: =(D23-D$11)/D$11*100 -> -12.610285 | M23: =(E23-E$11)/E$11*100 -> -4.1110967 | N23: =(F23-F$11)/F$11*100 -> -0.074542725 | O23: =(G23-G$11)/G$11*100 -> 9.1145586 | Q23: short | R23: stiff | S23: =(H23-H$11)/H$11*100 -> -11.916188
A24: short | B24: stiff2 | D24: 14.097684 | E24: 15.998829 | F24: 17.923101 | G24: 19.778831 | H24: =E24 -> 15.998829 | I24: short | J24: stiff2 | L24: =(D24-D$11)/D$11*100 -> -6.2876369 | M24: =(E24-E$11)/E$11*100 -> 8.8332689 | N24: =(F24-F$11)/F$11*100 -> 11.99906 | O24: =(G24-G$11)/G$11*100 -> 22.138905 | Q24: short | R24: stiff2 | S24: =(H24-H$11)/H$11*100 -> -0.025457881
A26: long | B26: compliant2 | D26: 14.728845 | E26: 14.581715 | F26: 15.542989 | G26: 15.79303 | H26: =E26 -> 14.581715 | I26: long | J26: compliant2 | L26: =(D26-D$11)/D$11*100 -> -2.0920833 | M26: =(E26-E$11)/E$11*100 -> -0.80675844 | N26: =(F26-F$11)/F$11*100 -> -2.8739411 | O26: =(G26-G$11)/G$11*100 -> -2.4743482 | Q26: long | R26: compliant2 | S26: =(H26-H$11)/H$11*100 -> -8.8808137
A27: long | B27: compliant | D27: 14.432468 | E27: 14.198001 | F27: 14.952511 | G27: 15.667849 | H27: =E27 -> 14.198001 | I27: long | J27: compliant | L27: =(D27-D$11)/D$11*100 -> -4.0622076 | M27: =(E27-E$11)/E$11*100 -> -3.4170025 | N27: =(F27-F$11)/F$11*100 -> -6.5637591 | O27: =(G27-G$11)/G$11*100 -> -3.2473702 | Q27: long | R27: compliant | S27: =(H27-H$11)/H$11*100 -> -11.278591
A28: long | B28: nom | D28: 13.895264 | E28: 13.335151 | F28: 14.719719 | G28: 15.267431 | H28: =E28 -> 13.335151 | I28: long | J28: nom | L28: =(D28-D$11)/D$11*100 -> -7.6331953 | M28: =(E28-E$11)/E$11*100 -> -9.2866062 | N28: =(F28-F$11)/F$11*100 -> -8.0184452 | O28: =(G28-G$11)/G$11*100 -> -5.7200449 | Q28: long | R28: nom | S28: =(H28-H$11)/H$11*100 -> -16.670425
A29: long | B29: stiff | D29: 13.319225 | E29: 12.986894 | F29: 14.458045 | G29: 15.71936 | H29: =E29 -> 12.986894 | I29: long | J29: stiff | L29: =(D29-D$11)/D$11*100 -> -11.462333 | M29: =(E29-E$11)/E$11*100 -> -11.655651 | N29: =(F29-F$11)/F$11*100 -> -9.653611 | O29: =(G29-G$11)/G$11*100 -> -2.9292777 | Q29: long | R29: stiff | S29: =(H29-H$11)/H$11*100 -> -18.846637
A30: long | B30: stiff2 | D30: 15.71936 | E30: 13.016788 | F30: 14.871712 | G30: 16.444382 | H30: =E30 -> 13.016788 | I30: long | J30: stiff2 | L30: =(D30-D$11)/D$11*100 -> 4.4922252 | M30: =(E30-E$11)/E$11*100 -> -11.452295 | N30: =(F30-F$11)/F$11*100 -> -7.0686612 | O30: =(G30-G$11)/G$11*100 -> 1.5479026 | Q30: long | R30: stiff2 | S30: =(H30-H$11)/H$11*100 -> -18.659833
A32: short2 | B32: compliant2 | D32: 14.413826 | E32: 14.091381 | F32: 14.89953 | G32: 15.441828 | H32: =E32 -> 14.091381 | I32: short2 | J32: compliant2 | L32: =(D32-D$11)/D$11*100 -> -4.1861276 | M32: =(E32-E$11)/E$11*100 -> -4.1422933 | N32: =(F32-F$11)/F$11*100 -> -6.8948303 | O32: =(G32-G$11)/G$11*100 -> -4.6431027 | Q32: short2 | R32: compliant2 | S32: =(H32-H$11)/H$11*100 -> -11.944845
A33: short2 | B33: compliant | D33: 13.823103 | E33: 13.329852 | F33: 14.432667 | G33: 15.046615 | H33: =E33 -> 13.329852 | I33: short2 | J33: compliant | L33: =(D33-D$11)/D$11*100 -> -8.1128753 | M33: =(E33-E$11)/E$11*100 -> -9.3226531 | N33: =(F33-F$11)/F$11*100 -> -9.8121947 | O33: =(G33-G$11)/G$11*100 -> -7.0836353 | Q33: short2 | R33: compliant | S33: =(H33-H$11)/H$11*100 -> -16.703538
A34: short2 | B34: nom | D34: 13.054639 | E34: 13.129009 | F34: 14.833463 | G34: 16.575775 | H34: =E34 -> 13.129009 | I34: short2 | J34: nom | L34: =(D34-D$11)/D$11*100 -> -13.221131 | M34: =(E34-E$11)/E$11*100 -> -10.688903 | N34: =(F34-F$11)/F$11*100 -> -7.3076741 | O34: =(G34-G$11)/G$11*100 -> 2.3592851 | Q34: short2 | R34: nom | S34: =(H34-H$11)/H$11*100 -> -17.958579
A35: short2 | B35: stiff | D35: 13.410028 | E35: 14.990991 | F35: 16.641729 | G35: 18.651879 | H35: =E35 -> 14.990991 | I35: short2 | J35: stiff | L35: =(D35-D$11)/D$11*100 -> -10.858733 | M35: =(E35-E$11)/E$11*100 -> 1.9773731 | N35: =(F35-F$11)/F$11*100 -> 3.9919382 | O35: =(G35-G$11)/G$11*100 -> 15.179713 | Q35: short2 | R35: stiff | S35: =(H35-H$11)/H$11*100 -> -6.3233027
A36: short2 | B36: stiff2 | D36: 14.964581 | E36: 17.199712 | F36: 19.160046 | G36: 20.985304 | H36: =E36 -> 17.199712 | I36: short2 | J36: stiff2 | L36: =(D36-D$11)/D$11*100 -> -0.52506157 | M36: =(E36-E$11)/E$11*100 -> 17.002368 | N36: =(F36-F$11)/F$11*100 -> 19.728564 | O36: =(G36-G$11)/G$11*100 -> 29.589157 | Q36: short2 | R36: stiff2 | S36: =(H36-H$11)/H$11*100 -> 7.4786993
... A42: long2 | B42: stiff2 | D42: 13.621804 | E42: 13.136628 | F42: 14.628198 | G42: 15.523333 | H42: =E42 -> 13.136628 | I42: long2 | J42: stiff2 | L42: =(D42-D$11)/D$11*100 -> -9.450982 | M42: =(E42-E$11)/E$11*100 -> -10.637074 | N42: =(F42-F$11)/F$11*100 -> -8.5903476 | O42: =(G42-G$11)/G$11*100 -> -4.1397902 | Q42: long2 | R42: stiff2 | S42: =(H42-H$11)/H$11*100 -> -17.910969
H45: =E45 -> 0
H46: =E46 -> 0
H47: =E47 -> 0
H48: =E48 -> 0
H49: =E49 -> 0
H50: =E50 -> 0
H51: =E51 -> 0

Sheet 2.7 grid 12.24
Z5: lengths | AA5: 0.0718 | AB5: =AC5/2 -> 0.14345 | AC5: 0.2869 | AD5: 0.4305 | AE5: 0.5741
Z6: stiff | AA6: 30 | AB6: 60 | AC6: 120 | AD6: 180 | AE6: 240
B7: metabolic values | I7: percent savings | Q7: Bottom of the bowl savings. | U7: Table
B8: time | C8: 0.568 | D8: 0.608 | E8: 0.648 | F8: 0.6835 | G8: 0.7235 | I8: time | L8: 0.608 | M8: 0.648 | N8: 0.6835 | O8: 0.7235
V9: Percent change Natural to Exotendon 2.7 m/s | X9: exotendon length (m)
H10: minimums | X10: l=0.0718 | Y10: l=0.1435 | Z10: l=0.2869 | AA10: l=0.4305 | AB10: l=0.5741
B11: natural | D11: 11.308961 | E11: 11.120588 | F11: 11.069881 | G11: 11.199204 | H11: =F11 -> 11.069881 | J11: natural | R11: natural | V11: exotendon stiffness (N/m) | W11: 30 | X11: -2.6842565 | Y11: -1.7121322 | Z11: -1.4163296 | AA11: -0.43584028 | AB11: 0.31237915
W12: 60 | X12: -4.1826285 | Y12: -4.5422801 | Z12: -3.1454629 | AA12: -1.3899427 | AB12: 0.17563874
A13: length | B13: stiff | I13: length | J13: stiff | Q13: length | R13: stiff | W13: 120 | X13: -2.1029765 | Y13: -3.6342848 | Z13: -5.1817992 | AA13: -3.2651119 | AB13: 0.041536129
A14: nom | B14: compliant2 | D14: 11.108798 | E14: 10.913095 | F14: 10.850683 | G14: 10.980335 | H14: =E14 -> 10.913095 | I14: nom | J14: compliant2 | L14: =(D14-D$11)/D$11*100 -> -1.7699504 | M14: =(E14-E$11)/E$11*100 -> -1.8658456 | N14: =(F14-F$11)/F$11*100 -> -1.9801297 | O14: =(G14-G$11)/G$11*100 -> -1.9543264 | Q14: nom | R14: compliant2 | S14: =(H14-H$11)/H$11*100 -> -1.4163296 | W14: 180 | X14: 4.6568071 | Y14: 1.0140398 | Z14: -5.092566 | AA14: -3.8418932 | AB14: -0.066233774
A15: nom | B15: compliant | D15: 10.918384 | E15: 10.721682 | F15: 10.657762 | G15: 11.677771 | H15: =E15 -> 10.721682 | I15: nom | J15: compliant | L15: =(D15-D$11)/D$11*100 -> -3.4536948 | M15: =(E15-E$11)/E$11*100 -> -3.5870945 | N15: =(F15-F$11)/F$11*100 -> -3.7228855 | O15: =(G15-G$11)/G$11*100 -> 4.2732233 | Q15: nom | R15: compliant | S15: =(H15-H$11)/H$11*100 -> -3.1454629 | W15: 240 | X15: 12.444714 | Y15: 6.2852528 | Z15: -2.4330975 | AA15: -5.0798649 | AB15: -1.0107335
A16: nom | B16: nom | D16: 10.619084 | E16: 10.496262 | F16: 10.59448 | G16: 11.753566 | H16: =E16 -> 10.496262 | I16: nom | J16: nom | L16: =(D16-D$11)/D$11*100 -> -6.1002686 | M16: =(E16-E$11)/E$11*100 -> -5.6141456 | N16: =(F16-F$11)/F$11*100 -> -4.2945448 | O16: =(G16-G$11)/G$11*100 -> 4.9500125 | Q16: nom | R16: nom | S16: =(H16-H$11)/H$11*100 -> -5.1817992
A17: nom | B17: stiff | D17: 10.394321 | E17: 10.50614 | F17: 10.919468 | G17: 12.16298 | H17: =E17 -> 10.50614 | I17: nom | J17: stiff | L17: =(D17-D$11)/D$11*100 -> -8.0877456 | M17: =(E17-E$11)/E$11*100 -> -5.5253193 | N17: =(F17-F$11)/F$11*100 -> -1.358759 | O17: =(G17-G$11)/G$11*100 -> 8.6057545 | Q17: nom | R17: stiff | S17: =(H17-H$11)/H$11*100 -> -5.092566
A18: nom | B18: stiff2 | D18: 10.378399 | E18: 10.80054 | F18: 11.256772 | G18: 12.635011 | H18: =E18 -> 10.80054 | I18: nom | J18: stiff2 | L18: =(D18-D$11)/D$11*100 -> -8.2285366 | M18: =(E18-E$11)/E$11*100 -> -2.8779773 | N18: =(F18-F$11)/F$11*100 -> 1.6882837 | O18: =(G18-G$11)/G$11*100 -> 12.820617 | Q18: nom | R18: stiff2 | S18: =(H18-H$11)/H$11*100 -> -2.4330975
A20: short | B20: compliant2 | D20: 11.009072 | E20: 10.88035 | F20: 10.764243 | G20: 10.932705 | H20: =E20 -> 10.88035 | I20: short | J20: compliant2 | L20: =(D20-D$11)/D$11*100 -> -2.6517821 | M20: =(E20-E$11)/E$11*100 -> -2.1602994 | N20: =(F20-F$11)/F$11*100 -> -2.7609872 | O20: =(G20-G$11)/G$11*100 -> -2.3796245 | Q20: short | R20: compliant2 | S20: =(H20-H$11)/H$11*100 -> -1.7121322
A21: short | B21: compliant | D21: 10.759329 | E21: 10.567056 | F21: 10.573487 | G21: 11.662921 | H21: =E21 -> 10.567056 | I21: short | J21: compliant | L21: =(D21-D$11)/D$11*100 -> -4.8601459 | M21: =(E21-E$11)/E$11*100 -> -4.9775426 | N21: =(F21-F$11)/F$11*100 -> -4.4841855 | O21: =(G21-G$11)/G$11*100 -> 4.1406246 | Q21: short | R21: compliant | S21: =(H21-H$11)/H$11*100 -> -4.5422801
A22: short | B22: nom | D22: 10.495385 | E22: 10.66757 | F22: 11.018117 | G22: 12.269337 | H22: =E22 -> 10.66757 | I22: short | J22: nom | L22: =(D22-D$11)/D$11*100 -> -7.1940826 | M22: =(E22-E$11)/E$11*100 -> -4.0736875 | N22: =(F22-F$11)/F$11*100 -> -0.46761117 | O22: =(G22-G$11)/G$11*100 -> 9.555438 | Q22: short | R22: nom | S22: =(H22-H$11)/H$11*100 -> -3.6342848
A23: short | B23: stiff | D23: 10.615292 | E23: 11.182134 | F23: 11.561756 | G23: 13.064632 | H23: =E23 -> 11.182134 | I23: short | J23: stiff | L23: =(D23-D$11)/D$11*100 -> -6.1337996 | M23: =(E23-E$11)/E$11*100 -> 0.55344196 | N23: =(F23-F$11)/F$11*100 -> 4.443363 | O23: =(G23-G$11)/G$11*100 -> 16.656791 | Q23: short | R23: stiff | S23: =(H23-H$11)/H$11*100 -> 1.0140398
A24: short | B24: stiff2 | D24: 11.230423 | E24: 11.765651 | F24: 12.152825 | G24: 13.876482 | H24: =E24 -> 11.765651 | I24: short | J24: stiff2 | L24: =(D24-D$11)/D$11*100 -> -0.69447582 | M24: =(E24-E$11)/E$11*100 -> 5.8006195 | N24: =(F24-F$11)/F$11*100 -> 9.7827971 | O24: =(G24-G$11)/G$11*100 -> 23.905967 | Q24: short | R24: stiff2 | S24: =(H24-H$11)/H$11*100 -> 6.2852528
A26: long | B26: compliant2 | D26: 11.223574 | E26: 11.021634 | F26: 10.964835 | G26: 11.866345 | H26: =E26 -> 11.021634 | I26: long | J26: compliant2 | L26: =(D26-D$11)/D$11*100 -> -0.75503842 | M26: =(E26-E$11)/E$11*100 -> -0.88982705 | N26: =(F26-F$11)/F$11*100 -> -0.94893522 | O26: =(G26-G$11)/G$11*100 -> 5.9570394 | Q26: long | R26: compliant2 | S26: =(H26-H$11)/H$11*100 -> -0.43584028
A27: long | B27: compliant | D27: 11.147981 | E27: 10.916016 | F27: 10.850552 | G27: 10.959847 | H27: =E27 -> 10.916016 | I27: long | J27: compliant | L27: =(D27-D$11)/D$11*100 -> -1.4234729 | M27: =(E27-E$11)/E$11*100 -> -1.839579 | N27: =(F27-F$11)/F$11*100 -> -1.9813131 | O27: =(G27-G$11)/G$11*100 -> -2.137268 | Q27: long | R27: compliant | S27: =(H27-H$11)/H$11*100 -> -1.3899427
A28: long | B28: nom | D28: 10.998482 | E28: 10.708437 | F28: 10.636528 | G28: 11.66716 | H28: =E28 -> 10.708437 | I28: long | J28: nom | L28: =(D28-D$11)/D$11*100 -> -2.7454246 | M28: =(E28-E$11)/E$11*100 -> -3.7061979 | N28: =(F28-F$11)/F$11*100 -> -3.9147033 | O28: =(G28-G$11)/G$11*100 -> 4.1784755 | Q28: long | R28: nom | S28: =(H28-H$11)/H$11*100 -> -3.2651119
A29: long | B29: stiff | D29: 10.790494 | E29: 10.644588 | F29: 10.548038 | G29: 11.725153 | H29: =E29 -> 10.644588 | I29: long | J29: stiff | L29: =(D29-D$11)/D$11*100 -> -4.5845679 | M29: =(E29-E$11)/E$11*100 -> -4.2803492 | N29: =(F29-F$11)/F$11*100 -> -4.7140796 | O29: =(G29-G$11)/G$11*100 -> 4.696307 | Q29: long | R29: stiff | S29: =(H29-H$11)/H$11*100 -> -3.8418932
... A42: long2 | B42: stiff2 | D42: 11.252209 | E42: 10.957994 | F42: 10.836492 | G42: 11.779784 | H42: =E42 -> 10.957994 | I42: long2 | J42: stiff2 | L42: =(D42-D$11)/D$11*100 -> -0.50183213 | M42: =(E42-E$11)/E$11*100 -> -1.4620989 | N42: =(F42-F$11)/F$11*100 -> -2.1083244 | O42: =(G42-G$11)/G$11*100 -> 5.1841184 | Q42: long2 | R42: stiff2 | S42: =(H42-H$11)/H$11*100 -> -1.0107335
H45: =E45 -> 0
H46: =E46 -> 0
H47: =E47 -> 0
H48: =E48 -> 0
H49: =E49 -> 0
H50: =E50 -> 0
H51: =E51 -> 0

Sheet 4 grid 12.24 (2)
AB5: lengths | AC5: 0.0718 | AD5: =AE5/2 -> 0.14345 | AE5: 0.2869 | AF5: 0.4305 | AG5: 0.5741
AB6: stiff | AC6: 30 | AD6: 60 | AE6: 120 | AF6: 180 | AG6: 240
B7: metabolic values | K7: percent savings | S7: Bottom of the bowl savings. | W7: Table
B8: time | C8: 0.564 | D8: 0.604 | E8: 0.644 | F8: 0.684 | G8: 0.724 | K8: time | N8: 0.608 | O8: 0.648 | P8: 0.6835 | Q8: 0.7235
X9: Percent change Natural to Exotendon 4.0 m/s | Z9: exotendon length (m)
H10: minimums | I10: min time | J10: cadence | Z10: l=0.0718 | AA10: l=0.1435 | AB10: l=0.2869 | AC10: l=0.4305 | AD10: l=0.5741
B11: natural | D11: 15.310265 | E11: 15.048802 | F11: 16.300446 | G11: 16.45914 | H11: =F11 -> 16.300446 | I11: 0.644 | J11: =2/I11*60 -> 186.3354 | L11: natural | T11: natural | X11: exotendon stiffness (N/m) | Y11: 30 | Z11: -11.315108 | AA11: -10.670444 | AB11: -9.8981402 | AC11: -8.2956074 | AD11: -7.731678
Y12: 60 | Z12: -16.799375 | AA12: -16.040567 | AB12: -13.404412 | AC12: -11.296789 | AD12: -9.4310487
A13: length | B13: stiff | K13: length | L13: stiff | S13: length | T13: stiff | Y13: 120 | Z13: -17.807163 | AA13: -18.494899 | AB13: -16.889697 | AC13: -16.548234 | AD13: -12.688303
A14: nom | B14: compliant2 | D14: 14.835711 | E14: 14.687005 | F14: 15.630247 | G14: 16.025826 | H14: =E14 -> 14.687005 | I14: 0.644 | J14: =2/I14*60 -> 186.3354 | K14: nom | L14: compliant2 | N14: =(D14-D$11)/D$11*100 -> -3.0995806 | O14: =(E14-E$11)/E$11*100 -> -2.4041582 | P14: =(F14-F$11)/F$11*100 -> -4.1115378 | Q14: =(G14-G$11)/G$11*100 -> -2.6326649 | S14: nom | T14: compliant2 | U14: =(H14-H$11)/H$11*100 -> -9.8981402 | Y14: 180 | Z14: -6.5106685 | AA14: -11.870859 | AB14: -17.673651 | AC14: -18.467574 | AD14: -15.774341
A15: nom | B15: compliant | D15: 14.39445 | E15: 14.115467 | F15: 15.148153 | G15: 15.814506 | H15: =E15 -> 14.115467 | I15: 0.644 | J15: =2/I15*60 -> 186.3354 | K15: nom | L15: compliant | N15: =(D15-D$11)/D$11*100 -> -5.9817057 | O15: =(E15-E$11)/E$11*100 -> -6.2020552 | P15: =(F15-F$11)/F$11*100 -> -7.0690888 | Q15: =(G15-G$11)/G$11*100 -> -3.9165716 | S15: nom | T15: compliant | U15: =(H15-H$11)/H$11*100 -> -13.404412 | Y15: 240 | Z15: 7.2577646 | AA15: -0.4543618 | AB15: -11.933262 | AC15: -18.258451 | AD15: -17.947362
A16: nom | B16: nom | D16: 13.699228 | E16: 13.54735 | F16: 14.632049 | G16: 16.051697 | H16: =E16 -> 13.54735 | I16: 0.644 | J16: =2/I16*60 -> 186.3354 | K16: nom | L16: nom | N16: =(D16-D$11)/D$11*100 -> -10.522594 | O16: =(E16-E$11)/E$11*100 -> -9.9772194 | P16: =(F16-F$11)/F$11*100 -> -10.235284 | Q16: =(G16-G$11)/G$11*100 -> -2.4754817 | S16: nom | T16: nom | U16: =(H16-H$11)/H$11*100 -> -16.889697
A17: nom | B17: stiff | D17: 13.234811 | E17: 13.419562 | F17: 15.240169 | G17: 17.092821 | H17: =E17 -> 13.419562 | I17: 0.604 | J17: =2/I17*60 -> 198.6755 | K17: nom | L17: stiff | N17: =(D17-D$11)/D$11*100 -> -13.555964 | O17: =(E17-E$11)/E$11*100 -> -10.826377 | P17: =(F17-F$11)/F$11*100 -> -6.5045889 | Q17: =(G17-G$11)/G$11*100 -> 3.850025 | S17: nom | T17: stiff | U17: =(H17-H$11)/H$11*100 -> -17.673651
A18: nom | B18: stiff2 | D18: 13.294829 | E18: 14.355271 | F18: 16.375259 | G18: 18.238565 | H18: =E18 -> 14.355271 | I18: 0.604 | J18: =2/I18*60 -> 198.6755 | K18: nom | L18: stiff2 | N18: =(D18-D$11)/D$11*100 -> -13.163952 | O18: =(E18-E$11)/E$11*100 -> -4.6085462 | P18: =(F18-F$11)/F$11*100 -> 0.4589629 | Q18: =(G18-G$11)/G$11*100 -> 10.811166 | S18: nom | T18: stiff2 | U18: =(H18-H$11)/H$11*100 -> -11.933262
A20: short | B20: compliant2 | D20: 14.711863 | E20: 14.561116 | F20: 15.461322 | G20: 15.872484 | H20: =E20 -> 14.561116 | I20: 0.644 | J20: =2/I20*60 -> 186.3354 | K20: short | L20: compliant2 | N20: =(D20-D$11)/D$11*100 -> -3.9085019 | O20: =(E20-E$11)/E$11*100 -> -3.2406965 | P20: =(F20-F$11)/F$11*100 -> -5.1478591 | Q20: =(G20-G$11)/G$11*100 -> -3.5643175 | S20: short | T20: compliant2 | U20: =(H20-H$11)/H$11*100 -> -10.670444
A21: short | B21: compliant | D21: 14.18617 | E21: 13.685762 | F21: 14.830165 | G21: 15.592643 | H21: =E21 -> 13.685762 | I21: 0.644 | J21: =2/I21*60 -> 186.3354 | K21: short | L21: compliant | N21: =(D21-D$11)/D$11*100 -> -7.3421002 | O21: =(E21-E$11)/E$11*100 -> -9.0574652 | P21: =(F21-F$11)/F$11*100 -> -9.019882 | Q21: =(G21-G$11)/G$11*100 -> -5.2645339 | S21: short | T21: compliant | U21: =(H21-H$11)/H$11*100 -> -16.040567
A22: short | B22: nom | D22: 13.370756 | E22: 13.285695 | F22: 14.831022 | G22: 16.492589 | H22: =E22 -> 13.285695 | I22: 0.644 | J22: =2/I22*60 -> 186.3354 | K22: short | L22: nom | N22: =(D22-D$11)/D$11*100 -> -12.66803 | O22: =(E22-E$11)/E$11*100 -> -11.715929 | P22: =(F22-F$11)/F$11*100 -> -9.0146245 | Q22: =(G22-G$11)/G$11*100 -> 0.20322447 | S22: short | T22: nom | U22: =(H22-H$11)/H$11*100 -> -18.494899
A23: short | B23: stiff | D23: 13.430968 | E23: 14.365443 | F23: 16.272478 | G23: 18.043804 | H23: =E23 -> 14.365443 | I23: 0.604 | J23: =2/I23*60 -> 198.6755 | K23: short | L23: stiff | N23: =(D23-D$11)/D$11*100 -> -12.274752 | O23: =(E23-E$11)/E$11*100 -> -4.5409528 | P23: =(F23-F$11)/F$11*100 -> -0.17157813 | Q23: =(G23-G$11)/G$11*100 -> 9.6278663 | S23: short | T23: stiff | U23: =(H23-H$11)/H$11*100 -> -11.870859
A24: short | B24: stiff2 | D24: 14.327765 | E24: 16.226383 | F24: 18.204845 | G24: 20.110809 | H24: =E24 -> 16.226383 | I24: 0.604 | J24: =2/I24*60 -> 198.6755 | K24: short | L24: stiff2 | N24: =(D24-D$11)/D$11*100 -> -6.4172632 | O24: =(E24-E$11)/E$11*100 -> 7.8250814 | P24: =(F24-F$11)/F$11*100 -> 11.68311 | Q24: =(G24-G$11)/G$11*100 -> 22.186269 | S24: short | T24: stiff2 | U24: =(H24-H$11)/H$11*100 -> -0.4543618
A26: long | B26: compliant2 | D26: 14.983318 | E26: 14.948225 | F26: 15.784384 | G26: 16.292808 | H26: =E26 -> 14.948225 | I26: 0.644 | J26: =2/I26*60 -> 186.3354 | K26: long | L26: compliant2 | N26: =(D26-D$11)/D$11*100 -> -2.1354758 | O26: =(E26-E$11)/E$11*100 -> -0.66833891 | P26: =(F26-F$11)/F$11*100 -> -3.1659379 | Q26: =(G26-G$11)/G$11*100 -> -1.0105753 | S26: long | T26: compliant2 | U26: =(H26-H$11)/H$11*100 -> -8.2956074
A27: long | B27: compliant | D27: 14.671505 | E27: 14.459019 | F27: 15.455528 | G27: 15.803293 | H27: =E27 -> 14.459019 | I27: 0.644 | J27: =2/I27*60 -> 186.3354 | K27: long | L27: compliant | N27: =(D27-D$11)/D$11*100 -> -4.1721028 | O27: =(E27-E$11)/E$11*100 -> -3.9191359 | P27: =(F27-F$11)/F$11*100 -> -5.1834042 | Q27: =(G27-G$11)/G$11*100 -> -3.9846979 | S27: long | T27: compliant | U27: =(H27-H$11)/H$11*100 -> -11.296789
A28: long | B28: nom | D28: 14.044463 | E28: 13.60301 | F28: 14.88682 | G28: 15.536303 | H28: =E28 -> 13.60301 | I28: 0.644 | J28: =2/I28*60 -> 186.3354 | K28: long | L28: nom | N28: =(D28-D$11)/D$11*100 -> -8.2676688 | O28: =(E28-E$11)/E$11*100 -> -9.6073561 | P28: =(F28-F$11)/F$11*100 -> -8.6723149 | Q28: =(G28-G$11)/G$11*100 -> -5.6068361 | S28: long | T28: nom | U28: =(H28-H$11)/H$11*100 -> -16.548234
A29: long | B29: stiff | D29: 13.641543 | E29: 13.290149 | F29: 14.68605 | G29: 15.951405 | H29: =E29 -> 13.290149 | I29: 0.644 | J29: =2/I29*60 -> 186.3354 | K29: long | L29: stiff | N29: =(D29-D$11)/D$11*100 -> -10.899367 | O29: =(E29-E$11)/E$11*100 -> -11.686332 | P29: =(F29-F$11)/F$11*100 -> -9.9039989 | Q29: =(G29-G$11)/G$11*100 -> -3.084821 | S29: long | T29: stiff | U29: =(H29-H$11)/H$11*100 -> -18.467574
... A42: long2 | B42: stiff2 | D42: 13.883046 | E42: 13.374946 | F42: 14.838291 | G42: 15.779356 | H42: =E42 -> 13.374946 | I42: 0.644 | J42: =2/I42*60 -> 186.3354 | K42: long2 | L42: stiff2 | N42: =(D42-D$11)/D$11*100 -> -9.3219745 | O42: =(E42-E$11)/E$11*100 -> -11.122852 | P42: =(F42-F$11)/F$11*100 -> -8.9700306 | Q42: =(G42-G$11)/G$11*100 -> -4.1301307 | S42: long2 | T42: stiff2 | U42: =(H42-H$11)/H$11*100 -> -17.947362
H45: =E45 -> 0
H46: =E46 -> 0
H47: =E47 -> 0
H48: =E48 -> 0
H49: =E49 -> 0
H50: =E50 -> 0
H51: =E51 -> 0

Sheet 2.7 grid 12.24_actualmin
Z5: lengths | AA5: 0.0718 | AB5: =AC5/2 -> 0.14345 | AC5: 0.2869 | AD5: 0.4305 | AE5: 0.5741
Z6: stiff | AA6: 30 | AB6: 60 | AC6: 120 | AD6: 180 | AE6: 240
B7: metabolic values | I7: percent savings | Q7: Bottom of the bowl savings. | U7: Table
B8: time | C8: 0.568 | D8: 0.608 | E8: 0.648 | F8: 0.6835 | G8: 0.7235 | I8: time | L8: 0.608 | M8: 0.648 | N8: 0.6835 | O8: 0.7235 | V8: set frequency
V9: Percent change Natural to Exotendon 2.7 m/s | X9: exotendon length (m)
H10: minimums | X10: l=0.0718 | Y10: l=0.1435 | Z10: l=0.2869 | AA10: l=0.4305 | AB10: l=0.5741
B11: natural | D11: 11.308961 | E11: 11.120588 | F11: 11.069881 | G11: 11.199204 | H11: =MIN(D11:G11) -> 11.069881 | J11: natural | R11: natural | V11: exotendon stiffness (N/m) | W11: 30 | X11: -2.6842565 | Y11: -1.7121322 | Z11: -1.4163296 | AA11: -0.43584028 | AB11: 0.31237915
W12: 60 | X12: -4.1826285 | Y12: -4.5422801 | Z12: -3.1454629 | AA12: -1.3899427 | AB12: 0.17563874
A13: length | B13: stiff | I13: length | J13: stiff | Q13: length | R13: stiff | W13: 120 | X13: -2.1029765 | Y13: -3.6342848 | Z13: -5.1817992 | AA13: -3.2651119 | AB13: 0.041536129
A14: nom | B14: compliant2 | D14: 11.108798 | E14: 10.913095 | F14: 10.850683 | G14: 10.980335 | H14: =MIN(D14:G14) -> 10.850683 | I14: nom | J14: compliant2 | L14: =(D14-D$11)/D$11*100 -> -1.7699504 | M14: =(E14-E$11)/E$11*100 -> -1.8658456 | N14: =(F14-F$11)/F$11*100 -> -1.9801297 | O14: =(G14-G$11)/G$11*100 -> -1.9543264 | Q14: nom | R14: compliant2 | S14: =(H14-H$11)/H$11*100 -> -1.9801297 | W14: 180 | X14: 4.6568071 | Y14: 1.0140398 | Z14: -5.092566 | AA14: -3.8418932 | AB14: -0.066233774
A15: nom | B15: compliant | D15: 10.918384 | E15: 10.721682 | F15: 10.657762 | G15: 11.677771 | H15: =MIN(D15:G15) -> 10.657762 | I15: nom | J15: compliant | L15: =(D15-D$11)/D$11*100 -> -3.4536948 | M15: =(E15-E$11)/E$11*100 -> -3.5870945 | N15: =(F15-F$11)/F$11*100 -> -3.7228855 | O15: =(G15-G$11)/G$11*100 -> 4.2732233 | Q15: nom | R15: compliant | S15: =(H15-H$11)/H$11*100 -> -3.7228855 | W15: 240 | X15: 12.444714 | Y15: 6.2852528 | Z15: -2.4330975 | AA15: -5.0798649 | AB15: -1.0107335
A16: nom | B16: nom | D16: 10.619084 | E16: 10.496262 | F16: 10.59448 | G16: 11.753566 | H16: =MIN(D16:G16) -> 10.496262 | I16: nom | J16: nom | L16: =(D16-D$11)/D$11*100 -> -6.1002686 | M16: =(E16-E$11)/E$11*100 -> -5.6141456 | N16: =(F16-F$11)/F$11*100 -> -4.2945448 | O16: =(G16-G$11)/G$11*100 -> 4.9500125 | Q16: nom | R16: nom | S16: =(H16-H$11)/H$11*100 -> -5.1817992
A17: nom | B17: stiff | D17: 10.394321 | E17: 10.50614 | F17: 10.919468 | G17: 12.16298 | H17: =MIN(D17:G17) -> 10.394321 | I17: nom | J17: stiff | L17: =(D17-D$11)/D$11*100 -> -8.0877456 | M17: =(E17-E$11)/E$11*100 -> -5.5253193 | N17: =(F17-F$11)/F$11*100 -> -1.358759 | O17: =(G17-G$11)/G$11*100 -> 8.6057545 | Q17: nom | R17: stiff | S17: =(H17-H$11)/H$11*100 -> -6.1026853
A18: nom | B18: stiff2 | D18: 10.378399 | E18: 10.80054 | F18: 11.256772 | G18: 12.635011 | H18: =MIN(D18:G18) -> 10.378399 | I18: nom | J18: stiff2 | L18: =(D18-D$11)/D$11*100 -> -8.2285366 | M18: =(E18-E$11)/E$11*100 -> -2.8779773 | N18: =(F18-F$11)/F$11*100 -> 1.6882837 | O18: =(G18-G$11)/G$11*100 -> 12.820617 | Q18: nom | R18: stiff2 | S18: =(H18-H$11)/H$11*100 -> -6.246517 | V18: actual min
V19: Percent change Natural to Exotendon 2.7 m/s | X19: exotendon length (m)
A20: short | B20: compliant2 | D20: 11.009072 | E20: 10.88035 | F20: 10.764243 | G20: 10.932705 | H20: =MIN(D20:G20) -> 10.764243 | I20: short | J20: compliant2 | L20: =(D20-D$11)/D$11*100 -> -2.6517821 | M20: =(E20-E$11)/E$11*100 -> -2.1602994 | N20: =(F20-F$11)/F$11*100 -> -2.7609872 | O20: =(G20-G$11)/G$11*100 -> -2.3796245 | Q20: short | R20: compliant2 | S20: =(H20-H$11)/H$11*100 -> -2.7609872 | X20: l=0.0718 | Y20: l=0.1435 | Z20: l=0.2869 | AA20: l=0.4305 | AB20: l=0.5741
A21: short | B21: compliant | D21: 10.759329 | E21: 10.567056 | F21: 10.573487 | G21: 11.662921 | H21: =MIN(D21:G21) -> 10.567056 | I21: short | J21: compliant | L21: =(D21-D$11)/D$11*100 -> -4.8601459 | M21: =(E21-E$11)/E$11*100 -> -4.9775426 | N21: =(F21-F$11)/F$11*100 -> -4.4841855 | O21: =(G21-G$11)/G$11*100 -> 4.1406246 | Q21: short | R21: compliant | S21: =(H21-H$11)/H$11*100 -> -4.5422801 | V21: exotendon stiffness (N/m) | W21: 30 | X21: -3.0146666 | Y21: -2.7609872 | Z21: -1.9801297 | AA21: -0.94893522 | AB21: -0.26699474
A22: short | B22: nom | D22: 10.495385 | E22: 10.66757 | F22: 11.018117 | G22: 12.269337 | H22: =MIN(D22:G22) -> 10.495385 | I22: short | J22: nom | L22: =(D22-D$11)/D$11*100 -> -7.1940826 | M22: =(E22-E$11)/E$11*100 -> -4.0736875 | N22: =(F22-F$11)/F$11*100 -> -0.46761117 | O22: =(G22-G$11)/G$11*100 -> 9.555438 | Q22: short | R22: nom | S22: =(H22-H$11)/H$11*100 -> -5.1897216 | W22: 60 | X22: -4.1826285 | Y22: -4.5422801 | Z22: -3.7228855 | AA22: -1.9813131 | AB22: -0.34766408
A23: short | B23: stiff | D23: 10.615292 | E23: 11.182134 | F23: 11.561756 | G23: 13.064632 | H23: =MIN(D23:G23) -> 10.615292 | I23: short | J23: stiff | L23: =(D23-D$11)/D$11*100 -> -6.1337996 | M23: =(E23-E$11)/E$11*100 -> 0.55344196 | N23: =(F23-F$11)/F$11*100 -> 4.443363 | O23: =(G23-G$11)/G$11*100 -> 16.656791 | Q23: short | R23: stiff | S23: =(H23-H$11)/H$11*100 -> -4.1065392 | W23: 120 | X23: -4.974796 | Y23: -5.1897216 | Z23: -5.1817992 | AA23: -3.9147033 | AB23: -0.85561895
